<?xml version="1.0"?>
<robot name="whill" xmlns:xacro="http://ros.org/wiki/xacro">

	<xacro:macro name="wheel_macro" params="parent prefix xyz rpy axis radius length mu1 mu2">
        <!-- drive Link -->
		<joint name="${prefix}_joint" type="continuous">
			<origin xyz="${xyz}" rpy="${rpy}" />
			<parent link="${parent}"/>
			<child  link="${prefix}"/>
			<axis xyz="${axis}"/>
		</joint>
		<link name="${prefix}">
			<inertial>
				<origin xyz="0 0 0" rpy="0 0 0" />
        <mass value="0.500"/>
        <inertia ixx="0.0013541667" ixy="0" ixz="0" iyy="0.0013541667" iyz="0" izz="0.0025"/>
			</inertial>
			<visual>
				<origin xyz="0 0 0" rpy="0 0 0" />
				<geometry>
					<cylinder radius="${radius}" length="${length}" />
				</geometry>
				<material name="red"/>
			</visual>
			<collision>
				<origin xyz="0 0 0" rpy="0 0 0" />
				<geometry>
					<cylinder radius="${radius}" length="${length}" />
				</geometry>
			</collision>
		</link>
		<gazebo reference="${prefix}">
			<material>Gazebo/Red</material>
			<selfCollide>true</selfCollide>
			<mu1 value="${mu1}" />
			<mu2 value="${mu2}" />
			<fdir1>0 0 1</fdir1>
		</gazebo>
	</xacro:macro>
</robot>